<?xml version="1.0" encoding="utf-8"?>
<!-- =================================================================================== -->
<!-- |    This document was autogenerated by xacro from edward.xacro                   | -->
<!-- |    EDITING THIS FILE BY HAND IS NOT RECOMMENDED                                 | -->
<!-- =================================================================================== -->
<robot name="edward">
  <material name="black">
    <color rgba="0.0 0.0 0.0 1.0"/>
  </material>
  <material name="blue">
    <color rgba="0.0 0.0 0.9 1.0"/>
  </material>
  <material name="green">
    <color rgba="0.0 0.8 0.0 1.0"/>
  </material>
  <material name="grey">
    <color rgba="0.2 0.2 0.2 1.0"/>
  </material>
  <material name="yellow">
    <color rgba="0.9 0.9 0.0 1.0"/>
  </material>
  <material name="orange">
    <color rgba="1.0 0.423529411765 0.0392156862745 1.0"/>
  </material>
  <material name="brown">
    <color rgba="0.60 0.30 0.0 1.0"/>
  </material>
  <material name="red">
    <color rgba="0.80078125 0.0 0.0 1.0"/>
  </material>
  <material name="white">
    <color rgba="1.0 1.0 1.0 1.0"/>
  </material>
  <!--<xacro:macro name="edward_arm" params="arm_id:='edward' description_pkg:='edwards_world' connected_to:='' xyz:='0 0 0' rpy:='0 0 0' safety_distance:=0">
    <xacro:unless value="${not connected_to}">
      <joint name="${arm_id}_joint_${connected_to}" type="fixed">
        <parent link="${connected_to}"/>
        <child link="${arm_id}_link0"/>
        <origin rpy="${rpy}" xyz="${xyz}"/>
      </joint>
    </xacro:unless>

-->
  <joint name="edward_arm_to_rightshoulder_joint" type="fixed">
    <parent link="right_shoulder"/>
    <child link="edward_link0"/>
    <origin rpy="0 0 0" xyz="0 0 0"/>
  </joint>
  <link name="edward_link0">
    <visual>
      <origin rpy="0 0 0" xyz="0 -0.0 0.02"/>
      <geometry>
        <cylinder length="0.04" radius="0.01"/>
      </geometry>
      <material name="blue"/>
    </visual>
    <collision>
      <origin rpy="0 0 0" xyz="0 -0.0 0.02"/>
      <geometry>
        <cylinder length="0.04" radius="0.01"/>
      </geometry>
      <material name="blue"/>
    </collision>
  </link>
  <link name="edward_link1">
    <visual>
      <origin rpy="1.57079632679 0 0" xyz="0 -0.01 0.0"/>
      <geometry>
        <cylinder length="0.02" radius="0.01"/>
      </geometry>
    </visual>
  </link>
  <!--1.  shoulder rotate -->
  <joint name="sr_joint" type="revolute">
    <axis xyz="0 0 1"/>
    <limit effort="5" lower="-1.3" upper="2.36" velocity="10"/>
    <origin rpy="0 0 0" xyz="0.0 -0.0 0.08"/>
    <parent link="edward_link0"/>
    <child link="edward_link1"/>
  </joint>
  <link name="edward_link2">
    <visual>
      <origin rpy="0 0 0" xyz="0 -0.06 0.0"/>
      <geometry>
        <box size="0.04 0.08 0.04"/>
      </geometry>
      <material name="green"/>
    </visual>
    <collision>
      <origin rpy="0 0 0" xyz="0 -0.06 0.0"/>
      <geometry>
         <box size="0.04 0.08 0.04"/>
      </geometry>
      
    </collision>
  </link>
  <!--2.  shoulder lift -->
  <joint name="sl_joint" type="revolute">
    <axis xyz="1 0 0"/>
    <limit effort="5" lower="-1.57079632679" upper="1.57079632679" velocity="10"/>
    <origin rpy="0 0 0" xyz="0.0 -0.035 0.00"/>
    <parent link="edward_link1"/>
    <child link="edward_link2"/>
  </joint>
  <link name="edward_link3">
    <visual>
      <origin rpy="1.57079632679 0 0" xyz="0 -0.0 0.0"/>
      <geometry>
        <cylinder length="0.03" radius="0.01"/>
      </geometry>
      <material name="orange"/>
    </visual>
    <collision>
      <origin rpy="1.57079632679 0 0" xyz="0 -0.0 0.0"/>
      <geometry>
        <cylinder length="0.03" radius="0.01"/>
      </geometry>
      <material name="orange"/>
    </collision>

  </link>
  <!--3.  elbow rotate -->
  <joint name="er_joint" type="revolute">
    <axis xyz="0 1 0"/>
    <limit effort="5" lower="-2.1" upper="2.1" velocity="10"/>
    <origin rpy="0 0 0" xyz="0.0 -0.13 0.0"/>
    <parent link="edward_link2"/>
    <child link="edward_link3"/>
  </joint>
  <!-- forearm-->
  <link name="edward_link4">
    <visual>
      <origin rpy="1.57079632679 0 0" xyz="0 -0.04 0.0"/>
      <geometry>
        <cylinder length="0.06" radius="0.01"/>
	      <box size="0.03 0.03 0.03"/>
      </geometry>
      <material name="white"/>
    </visual>
    <visual>
      <origin rpy="1.57079632679 0 0" xyz="0 -0.07 0.0"/>
      <geometry>
	    <box size="0.03 0.03 0.03"/>
      </geometry>
      <material name="white"/>
    </visual>

    <collision>
      <origin rpy="1.57079632679 0 0" xyz="0 -0.04 0.0"/>
      <geometry>
        <cylinder length="0.05" radius="0.01"/>
        <box size="0.02 0.02 0.02"/>
      </geometry>
    </collision>
    <collision>
     <origin rpy="1.57079632679 0 0" xyz="0 -0.07 0.0"/>
      <geometry>
        <box size="0.02 0.02 0.02"/>
      </geometry>
    </collision>
  </link>
  <!--4.  elbow lift X -->
  <joint name="el_joint" type="revolute">
    <axis xyz="0 0 -1"/>
    <limit effort="5" lower="-2.2" upper="0.0" velocity="10"/>
    <origin rpy="0 0 0" xyz="0.0 -0.055 0.0"/>
    <parent link="edward_link3"/>
    <child link="edward_link4"/>
  </joint>
  <link name="edward_link5">
    <visual>
      <origin rpy="1.57079632679 0 0" xyz="0 -0.0 0.0"/>
      <geometry>
        <cylinder length="0.03" radius="0.01"/>
      </geometry>
      <material name="blue"/>
    </visual>
    <collision>
      <origin rpy="1.57079632679 0 0" xyz="0 -0.0 0.0"/>
      <geometry>
        <cylinder length="0.03" radius="0.01"/>
      </geometry>
      <material name="blue"/>
    </collision>
  </link>
  <link name="elbow_pin"></link>
  <joint name="elbow_pin_joint" type="fixed">
    <origin rpy="0 0 0" xyz="0.0 -0.03 0.0"/>
    <parent link="edward_link4"/>
    <child link="elbow_pin"/>
  </joint>

  <!--4.  wrist rotate Y -->
  <joint name="wr_joint" type="revolute">
    <axis xyz="0 1 0"/>
    <limit effort="5" lower="-1.58" upper="1.58" velocity="10"/>
    <origin rpy="0 0 0" xyz="0.0 -0.12 0.0"/>
    <parent link="edward_link4"/>
    <child link="edward_link5"/>
  </joint>
  <link name="edward_link6">
    <visual>
      <origin rpy="0 0 0" xyz="0 -0.03 0.0"/>
      <geometry>
        <box size="0.03 0.03 0.01"/>
      </geometry>
      <material name="green"/>
    </visual>
    <collision>
      <origin rpy="0 0 0" xyz="0 -0.03 0.0"/>
      <geometry>
        <box size="0.03 0.03 0.01"/>
      </geometry>
      <material name="green"/>
    </collision>
  </link>
  <!--4.  wrist lift X -->
  <joint name="wl_joint" type="revolute">
    <axis xyz="0 0 -1"/>
    <limit effort="5" lower="-0.4" upper="0.3" velocity="10"/>
    <origin rpy="0 0 0" xyz="0.0 -0.05 0.0"/>
    <parent link="edward_link5"/>
    <child link="edward_link6"/>
  </joint>

  <link name="wrist_pin"></link>
  <joint name="wrist_pin_joint" type="fixed">
    <origin rpy="0 0 0" xyz="0.0 -0.027 0.0"/>
    <parent link="edward_link6"/>
    <child link="wrist_pin"/>
  </joint>

  <link name="edward_link7">
  </link>
  <!--4.  hand rotate Y -->
  <joint name="hr_joint" type="revolute">
    <axis xyz="0 1 0"/>
    <limit effort="5" lower="-0.5" upper="3.5" velocity="10"/>
    <origin rpy="0 0 0" xyz="0.0 -0.03 0.0"/>
    <parent link="edward_link6"/>
    <child link="edward_link7"/>
  </joint>
  <!-- hand -->
  <link name="edward_hand">
    <visual>
      <origin rpy="0 0 0.0" xyz="0 -0.03 -0.01"/>
      <geometry>
        <box size="0.03 0.05 0.03"/>
      </geometry>
      <material name="blue"/>
    </visual>
    <collision>
      <origin rpy="0 0 0.0" xyz="0 -0.03 -0.01"/>
      <geometry>
        <box size="0.03 0.05 0.03"/>
      </geometry>
    </collision>
  </link>
  <joint name="link7_to_hand_joint" type="fixed">
    <axis xyz="1 0 0"/>
    <limit effort="5" lower="-1.57079632679" upper="1.57079632679" velocity="10"/>
    <origin rpy="0 0 0" xyz="0.0 -0.05 0.0"/>
    <parent link="edward_link7"/>
    <child link="edward_hand"/>
  </joint>
  <!-- virtual middle finger -->
  <link name="edward_middlefinger"/>
  <joint name="hand_to_middlefinger_joint" type="fixed">
    <origin rpy="0 0 0" xyz="0.0 -0.12 0.0"/>
    <parent link="edward_hand"/>
    <child link="edward_middlefinger"/>
  </joint>

  <link name="edward_pointerfinger"/>
  <joint name="hand_to_pointerfinger_joint" type="fixed">
    <origin rpy="0 0 0" xyz="0.0 -0.12 0.025"/>
    <parent link="edward_hand"/>
    <child link="edward_pointerfinger"/>
  </joint>
  <!-- finger 1 -->
  <link name="edward_finger1">
    <visual>
      <origin rpy="0 0.0 0" xyz="-0.03 -0.06 0.03"/>
      <geometry>
        <box size="0.01 0.06 0.01"/>
      </geometry>
      <material name="yellow"/>
    </visual>
    <collision>
      <origin rpy="0 0.0 0" xyz="-0.03 -0.06 0.03"/>
      <geometry>
        <box size="0.01 0.06 0.01"/>
      </geometry>
    </collision>
  </link>
  <joint name="hand_to_finger1_joint" type="revolute">
    <axis xyz="0 0 1"/>
    <limit effort="5" lower="-1.57079632679" upper="1.57079632679" velocity="10"/>
    <origin rpy="0 0 0" xyz="0.0 0.0 0.0"/>
    <parent link="edward_hand"/>
    <child link="edward_finger1"/>
  </joint>
  <!-- finger 2 -->
  <link name="edward_finger2">
    <visual>
      <origin rpy="0 0.0 0" xyz="0.03 -0.06 0.03"/>
      <geometry>
        <box size="0.01 0.06 0.01"/>
      </geometry>
      <material name="yellow"/>
    </visual>
    <collision>
      <origin rpy="0 0.0 0" xyz="0.03 -0.06 0.03"/>
      <geometry>
        <box size="0.01 0.06 0.01"/>
      </geometry>
    </collision>
  </link>
  <joint name="hand_to_finger2_joint" type="revolute">
    <axis xyz="0 0 1"/>
    <limit effort="5" lower="-1.57079632679" upper="1.57079632679" velocity="10"/>
    <origin rpy="0 0 0" xyz="0.0 0.0 0.0"/>
    <parent link="edward_hand"/>
    <child link="edward_finger2"/>
    <mimic joint="hand_to_finger1_joint" multiplier="-1" offset="0"/>
  </joint>
  <!--</xacro:macro>-->
  <link name="link_chassis">
    <!-- pose and inertial -->
    <pose>0 0 0.1 0 0 0</pose>
    <inertial>
      <mass value="5"/>
      <origin rpy="0 0 0" xyz="0 0 0.04"/>
      <inertia ixx="0.0395416666667" ixy="0" ixz="0" iyy="0.106208333333" iyz="0" izz="0.106208333333"/>
    </inertial>
    <!-- body -->
    <collision name="collision_chassis">
      <geometry>
        <box size="0.31 0.35 0.03"/>
      </geometry>
    </collision>
    <visual>
      <origin rpy="0 0 0" xyz="0 0 0"/>
      <geometry>
        <box size="0.31 0.35 0.03"/>
      </geometry>
      <material name="orange"/>
    </visual>
  </link>
  <link name="link_right_casterwheel">
    <inertial>
      <mass value="0.2"/>
      <origin rpy="0 1.5707 1.5707" xyz="0 0 0"/>
      <inertia ixx="0.000526666666667" ixy="0" ixz="0" iyy="0.000526666666667" iyz="0" izz="0.001"/>
    </inertial>
    <collision name="link_right_wheel_collision">
      <origin rpy="0 1.5707 1.5707" xyz="0 0 0"/>
      <geometry>
        <cylinder length="0.02" radius="0.032"/>
      </geometry>
    </collision>
    <visual name="link_right_casterwheel_visual">
      <origin rpy="0 1.5707 1.5707" xyz="0 0 0"/>
      <geometry>
        <cylinder length="0.02" radius="0.032"/>
      </geometry>
      <material name="green"/>
    </visual>
  </link>
  <joint name="joint_right_casterwheel" type="continuous">
    <origin rpy="0 0 0" xyz="-0.15 0.20 0"/>
    <child link="link_right_casterwheel"/>
    <parent link="link_chassis"/>
    <axis rpy="0 0 0" xyz="0 1 0"/>
    <limit effort="10000" velocity="1000"/>
    <joint_properties damping="0.50" friction="0.50"/>
  </joint>
  <link name="link_left_casterwheel">
    <inertial>
      <mass value="0.2"/>
      <origin rpy="0 1.5707 1.5707" xyz="0 0 0"/>
      <inertia ixx="0.000526666666667" ixy="0" ixz="0" iyy="0.000526666666667" iyz="0" izz="0.001"/>
    </inertial>
    <collision name="link_right_wheel_collision">
      <origin rpy="0 1.5707 1.5707" xyz="0 0 0"/>
      <geometry>
        <cylinder length="0.02" radius="0.032"/>
      </geometry>
    </collision>
    <visual name="link_left_casterwheel_visual">
      <origin rpy="0 1.5707 1.5707" xyz="0 0 0"/>
      <geometry>
        <cylinder length="0.02" radius="0.032"/>
      </geometry>
      <material name="green"/>
    </visual>
  </link>
  <joint name="joint_left_casterwheel" type="continuous">
    <origin rpy="0 0 0" xyz="-0.15 -0.20 0"/>
    <child link="link_left_casterwheel"/>
    <parent link="link_chassis"/>
    <axis rpy="0 0 0" xyz="0 1 0"/>
    <limit effort="10000" velocity="1000"/>
    <joint_properties damping="0.50" friction="0.50"/>
  </joint>
  
  <joint name="joint_base_to_body" type="fixed">
    <origin rpy="0 0 0" xyz="0.0 0 1.0"/>
    <parent link="link_chassis"/>
    <child link="center_shoulder"/>
  </joint>


  <link name="link_right_wheel">
    <inertial>
      <mass value="0.2"/>
      <origin rpy="0 1.5707 1.5707" xyz="0 0 0"/>
      <inertia ixx="0.000526666666667" ixy="0" ixz="0" iyy="0.000526666666667" iyz="0" izz="0.001"/>
    </inertial>
    <collision name="link_right_wheel_collision">
      <origin rpy="0 1.5707 1.5707" xyz="0 0 0"/>
      <geometry>
        <cylinder length="0.02" radius="0.032"/>
      </geometry>
    </collision>
    <visual name="link_right_wheel_visual">
      <origin rpy="0 1.5707 1.5707" xyz="0 0 0"/>
      <geometry>
        <cylinder length="0.02" radius="0.032"/>
      </geometry>
      <material name="orange"/>
    </visual>
  </link>
  <joint name="joint_right_wheel" type="continuous">
    <origin rpy="0 0 0" xyz="0.15 -0.20 0"/>
    <child link="link_right_wheel"/>
    <parent link="link_chassis"/>
    <axis rpy="0 0 0" xyz="0 1 0"/>
    <limit effort="10000" velocity="1000"/>
    <joint_properties damping="0.50" friction="0.50"/>
  </joint>
  <link name="link_left_wheel">
    <inertial>
      <mass value="0.2"/>
      <origin rpy="0 1.5707 1.5707" xyz="0 0 0"/>
      <inertia ixx="0.00" ixy="0" ixz="0" iyy="0.000" iyz="0" izz="0.001"/>
    </inertial>
    <collision name="link_right_wheel_collision">
      <origin rpy="0 1.5707 1.5707" xyz="0 0 0"/>
      <geometry>
        <cylinder length="0.02" radius="0.032"/>
      </geometry>
    </collision>
    <visual name="link_left_wheel_visual">
      <origin rpy="0 1.5707 1.5707" xyz="0 0 0"/>
      <geometry>
        <cylinder length="0.02" radius="0.032"/>
      </geometry>
      <material name="blue"/>
    </visual>
  </link>
  <joint name="joint_left_wheel" type="continuous">
    <origin rpy="0 0 0" xyz="0.15 0.20 0"/>
    <child link="link_left_wheel"/>
    <parent link="link_chassis"/>
    <axis rpy="0 0 0" xyz="0 1 0"/>
    <limit effort="10000" velocity="1000"/>
    <joint_properties damping="0.50" friction="0.50"/>
  </joint>


  <link name="center_shoulder">
    <visual>
      <origin rpy="0 0 0" xyz="0 0 0"/>
      <geometry>
        <box size="0.06 0.44 0.06"/>
      </geometry>
      <material name="green"/>
    </visual>
    <collision>
      <origin rpy="0 0 0" xyz="0 0 0"/>
      <geometry>
        <box size="0.06 0.4 0.02"/>
      </geometry>
    </collision>
  </link>


  <link name="right_shoulder">
    <visual>
      <origin rpy="0 0 0" xyz="0 0 0"/>
      <geometry>
        <box size="0.02 0.0196 0.02"/>
      </geometry>
      <material name="green"/>
    </visual>
    <collision>
      <origin rpy="0 0 0" xyz="0 0 0"/>
      <geometry>
        <box size="0.02 0.02 0.02"/>
      </geometry>
    </collision>
  </link>
  <joint name="virtual_rightarm_joint" type="fixed">
    <origin rpy="0 0 0" xyz="0.005 -0.18 0.0"/>
    <parent link="center_shoulder"/>
    <child link="right_shoulder"/>
  </joint>
  <!--NEEDED FOR NECK COLLISSION-->
  <link name="neck">
    <visual>
      <origin rpy="0 0 0" xyz="0 0 0.1"/>
      <geometry>
        <box size="0.08 0.08 0.40"/>
      </geometry>
      <material name="green"/>
    </visual>
    <collision>
      <origin rpy="0 0 0" xyz="0 0 0.1"/>
      <geometry>
        <box size="0.08 0.08 0.4"/>
      </geometry>
    </collision>
  </link>
  <gazebo reference="neck">
    <material>Gazebo/Red</material>
  </gazebo>
  <joint name="joint_shoulder_to_neck" type="fixed">
    <origin rpy="0 0.0 0" xyz="0.0 0.014 0.435"/>
    <parent link="center_shoulder"/>
    <child link="neck"/>
  </joint>

  <link name="sensor_realsense">
    <inertial>
      <origin rpy="0 0.0 0" xyz="0 0 0"/>
      <mass value="0.25"/>
      <inertia ixx="0.00145833333333" ixy="0" ixz="0" iyy="0.00145833333333" iyz="0" izz="0.00125"/>
    </inertial>
    <visual>
      <origin rpy="0 0 0" xyz="0 0 0"/>
      <geometry>
        <cylinder length="0.2" radius="0.01"/>
      </geometry>
      <material name="red"/>
    </visual>
    <collision>
      <origin rpy="0 0 0" xyz="0 0 0"/>
      <geometry>
        <cylinder length="0.2" radius="0.01"/>
      </geometry>
    </collision>
  </link>
  <gazebo reference="sensor_realsense">
    <material>Gazebo/Green</material>
  </gazebo>
  <joint name="joint_sensor_realsense" type="fixed">
    <origin rpy="0 0 0" xyz="0.0 0.014 1.43"/>
    <parent link="link_chassis"/>
    <child link="sensor_realsense"/>
  </joint>

<link name="pan_link">
  </link>
 <joint name="neck_to_pan_joint" type="revolute">
     <axis xyz="0 0 1" />
	<limit lower="-1.57" upper="1.57" effort="5" velocity="10"/>
    <origin rpy="0.0 0.0 0" xyz="0.0 0.0 0.0"/>
    <parent link="sensor_realsense"/>
    <child link="pan_link"/>
  </joint>

  <link name="tilt_link2">
  </link>


  <joint name="neck_tilt_joint" type="revolute">
 <axis xyz="0 1 0" />
  <limit lower="-1.57" upper="1.57" effort="5" velocity="10"/>
    <!-- since the sensor_realsense is length="0.2", this moves it to the top -->
    <origin rpy="0.0 0.0 0" xyz="0.017 0.0 0.0"/>
    <parent link="pan_link"/>
    <child link="tilt_link2"/>
  </joint>

  <joint name="camera_rgb_joint" type="fixed">
    <origin rpy="0 0 0" xyz="0.10 0.016 0.037"/>  <!--The camera frame is actually at the left edge of the -->
    <parent link="tilt_link2"/>
    <child link="camera_link"/>
  </joint>
 
  

  <gazebo reference="link_right_wheel">
    <material>Gazebo/Orange</material>
  </gazebo>
  <gazebo reference="link_left_wheel">
    <material>Gazebo/Blue</material>
  </gazebo>
  <gazebo reference="link_tilt">
    <material>Gazebo/Orange</material>
  </gazebo>
  <gazebo reference="camera_link">
    <material>Gazebo/Black</material>
  </gazebo>
 <gazebo reference="camera_rgb_frame">
    <material>Gazebo/Yellow</material>
  </gazebo>
</robot>
